Workbook

Sheet הסבר
A1: תקציב לבניית בית פרטי - הסבר והוראות שימוש
B3: הקובץ כולל 4 גיליונות:
B4: • הסבר - הגיליון הנוכחי: הסבר כללי והוראות שימוש.
B5: • סיכום - תמונת מצב כוללת: ריכוז לפי קטגוריות ומדדים מרכזיים. כאן מגדירים את שטח הבנייה ואת שיעור המע"מ.
B6: • תקציב מפורט - 13 קטגוריות עם כל סעיפי העלות. כאן ממלאים מחירים ומעקבים תשלומים בפועל.
B7: • מימון ותזרים - מקורות המימון (הון עצמי, משכנתא) ופריסת תשלומים חודשית.
B9: איך לעבוד עם הקובץ:
B10: • תאים בצבע צהוב מיועדים להזנה ידנית - מחירים, כמויות ותשלומים בפועל.
B11: • כל שאר התאים מחושבים אוטומטית בנוסחאות - מומלץ לא לדרוס אותם.
B12: • המע"מ מחושב אוטומטית לפי השיעור שבגיליון "סיכום" (ברירת מחדל 18%).
B13: • סעיפים המסומנים כ"מ\"ר" עם כמות מופנים לשטח הבנייה - שינוי השטח מעדכן אותם אוטומטית.
B14: • סעיפים לא רלוונטיים - השאירו מחיר 0 (לא ישפיעו על הסיכום).
B16: הערות חשובות:
... B20: • הקובץ אינו תחליף לייעוץ מקצועי של אדריכל, מנהל פרויקט או שמאי.

Sheet סיכום
A1: סיכום תקציב - בניית בית פרטי
A3: הנחות יסוד ופרמטרים (ניתן לעריכה)
A4: שטח בנייה מתוכנן (מ"ר) | B4: 180
A5: שיעור מע"מ | B5: 0.18
A6: רזרבה מומלצת לבלת"מ | B6: 0.1
A8: ריכוז תקציב לפי קטגוריות
A9: קטגוריה | B9: מתוכנן (כולל מע"מ) | C9: שולם בפועל | D9: יתרה לתשלום | E9: % ביצוע
A10: 1. קרקע ועלויות רכישה | B10: ='תקציב מפורט'!G11 | C10: ='תקציב מפורט'!H11 | D10: ='תקציב מפורט'!I11 | E10: =IF(B10>0,C10/B10,0)
A11: 2. תכנון, ייעוץ והיתרים | B11: ='תקציב מפורט'!G21 | C11: ='תקציב מפורט'!H21 | D11: ='תקציב מפורט'!I21 | E11: =IF(B11>0,C11/B11,0)
A12: 3. עבודות עפר והכשרת קרקע | B12: ='תקציב מפורט'!G28 | C12: ='תקציב מפורט'!H28 | D12: ='תקציב מפורט'!I28 | E12: =IF(B12>0,C12/B12,0)
A13: 4. שלד ובטון | B13: ='תקציב מפורט'!G36 | C13: ='תקציב מפורט'!H36 | D13: ='תקציב מפורט'!I36 | E13: =IF(B13>0,C13/B13,0)
A14: 5. בנייה, מעטפת ואיטום | B14: ='תקציב מפורט'!G43 | C14: ='תקציב מפורט'!H43 | D14: ='תקציב מפורט'!I43 | E14: =IF(B14>0,C14/B14,0)
A15: 6. אלומיניום ונגרות חוץ | B15: ='תקציב מפורט'!G49 | C15: ='תקציב מפורט'!H49 | D15: ='תקציב מפורט'!I49 | E15: =IF(B15>0,C15/B15,0)
A16: 7. אינסטלציה ומערכות מים | B16: ='תקציב מפורט'!G56 | C16: ='תקציב מפורט'!H56 | D16: ='תקציב מפורט'!I56 | E16: =IF(B16>0,C16/B16,0)
A17: 8. חשמל, תקשורת ובית חכם | B17: ='תקציב מפורט'!G63 | C17: ='תקציב מפורט'!H63 | D17: ='תקציב מפורט'!I63 | E17: =IF(B17>0,C17/B17,0)
A18: 9. מיזוג אוויר | B18: ='תקציב מפורט'!G68 | C18: ='תקציב מפורט'!H68 | D18: ='תקציב מפורט'!I68 | E18: =IF(B18>0,C18/B18,0)
A19: 10. טיח, צבע, ריצוף וחיפוי | B19: ='תקציב מפורט'!G76 | C19: ='תקציב מפורט'!H76 | D19: ='תקציב מפורט'!I76 | E19: =IF(B19>0,C19/B19,0)
A20: 11. גמרים פנימיים | B20: ='תקציב מפורט'!G85 | C20: ='תקציב מפורט'!H85 | D20: ='תקציב מפורט'!I85 | E20: =IF(B20>0,C20/B20,0)
A21: 12. עבודות חוץ ופיתוח | B21: ='תקציב מפורט'!G93 | C21: ='תקציב מפורט'!H93 | D21: ='תקציב מפורט'!I93 | E21: =IF(B21>0,C21/B21,0)
A22: 13. ניהול, הובלה ובלת"מ | B22: ='תקציב מפורט'!G101 | C22: ='תקציב מפורט'!H101 | D22: ='תקציב מפורט'!I101 | E22: =IF(B22>0,C22/B22,0)
A23: סה"כ כללי | B23: =SUM(B10:B22) | C23: =SUM(C10:C22) | D23: =SUM(D10:D22) | E23: =IF(B23>0,C23/B23,0)
A25: מדדים מרכזיים
A26: סה"כ תקציב הפרויקט (כולל מע"מ) | D26: =B23
A27: סה"כ שולם עד כה | D27: =C23
A28: יתרה לתשלום | D28: =D23
A29: אחוז התקדמות כספי | D29: =E23
A30: עלות למ"ר (כולל מע"מ) | D30: =IF(B4>0,B23/B4,0)

Sheet תקציב מפורט
A1: תקציב מפורט - בניית בית פרטי
A2: תאים צהובים = להזנה ידנית | שאר התאים מחושבים אוטומטית | המע"מ לפי השיעור בגיליון "סיכום"
A4: סעיף | B4: יחידה | C4: כמות | D4: מחיר ליח' (ללא מע"מ) | E4: עלות מתוכננת (ללא מע"מ) | F4: מע"מ | G4: סה"כ מתוכנן (כולל מע"מ) | H4: שולם בפועל | I4: יתרה לתשלום | J4: % ביצוע | K4: הערות
A5: 1. קרקע ועלויות רכישה
A6: עלות המגרש / הקרקע | B6: קומפלט | C6: 1 | D6: 900000 | E6: =C6*D6 | F6: =E6*'סיכום'!$B$5 | G6: =E6+F6 | H6: 0 | I6: =G6-H6 | J6: =IF(G6>0,H6/G6,0) | K6: משתנה מאוד לפי אזור ומיקום
A7: מס רכישה | B7: קומפלט | C7: 1 | D7: 32000 | E7: =C7*D7 | F7: =E7*'סיכום'!$B$5 | G7: =E7+F7 | H7: 0 | I7: =G7-H7 | J7: =IF(G7>0,H7/G7,0) | K7: לפי מדרגות שווי
A8: שכ"ט עו"ד, אגרות ורישום בטאבו | B8: קומפלט | C8: 1 | D8: 15000 | E8: =C8*D8 | F8: =E8*'סיכום'!$B$5 | G8: =E8+F8 | H8: 0 | I8: =G8-H8 | J8: =IF(G8>0,H8/G8,0)
A9: דמי תיווך | B9: קומפלט | C9: 1 | D9: 0 | E9: =C9*D9 | F9: =E9*'סיכום'!$B$5 | G9: =E9+F9 | H9: 0 | I9: =G9-H9 | J9: =IF(G9>0,H9/G9,0) | K9: אם רלוונטי
A10: מדידה, מפה טופוגרפית ובדיקת קרקע | B10: קומפלט | C10: 1 | D10: 9000 | E10: =C10*D10 | F10: =E10*'סיכום'!$B$5 | G10: =E10+F10 | H10: 0 | I10: =G10-H10 | J10: =IF(G10>0,H10/G10,0)
A11: סה"כ 1. קרקע ועלויות רכישה | E11: =SUM(E6:E10) | F11: =SUM(F6:F10) | G11: =SUM(G6:G10) | H11: =SUM(H6:H10) | I11: =SUM(I6:I10) | J11: =IF(G11>0,H11/G11,0)
A13: 2. תכנון, ייעוץ והיתרים
A14: תכנון אדריכלי | B14: קומפלט | C14: 1 | D14: 55000 | E14: =C14*D14 | F14: =E14*'סיכום'!$B$5 | G14: =E14+F14 | H14: 0 | I14: =G14-H14 | J14: =IF(G14>0,H14/G14,0)
A15: מהנדס קונסטרוקציה | B15: קומפלט | C15: 1 | D15: 20000 | E15: =C15*D15 | F15: =E15*'סיכום'!$B$5 | G15: =E15+F15 | H15: 0 | I15: =G15-H15 | J15: =IF(G15>0,H15/G15,0)
A16: יועצים (קרקע, אינסטלציה, חשמל, בטיחות) | B16: קומפלט | C16: 1 | D16: 22000 | E16: =C16*D16 | F16: =E16*'סיכום'!$B$5 | G16: =E16+F16 | H16: 0 | I16: =G16-H16 | J16: =IF(G16>0,H16/G16,0)
A17: אגרות בנייה והיתר בנייה | B17: קומפלט | C17: 1 | D17: 45000 | E17: =C17*D17 | F17: =E17*'סיכום'!$B$5 | G17: =E17+F17 | H17: 0 | I17: =G17-H17 | J17: =IF(G17>0,H17/G17,0) | K17: תלוי רשות מקומית
A18: היטל השבחה | B18: קומפלט | C18: 1 | D18: 0 | E18: =C18*D18 | F18: =E18*'סיכום'!$B$5 | G18: =E18+F18 | H18: 0 | I18: =G18-H18 | J18: =IF(G18>0,H18/G18,0) | K18: אם חל
A19: חיבורי תשתית (חשמל, מים, ביוב, גז) | B19: קומפלט | C19: 1 | D19: 45000 | E19: =C19*D19 | F19: =E19*'סיכום'!$B$5 | G19: =E19+F19 | H19: 0 | I19: =G19-H19 | J19: =IF(G19>0,H19/G19,0)
A20: ניהול ופיקוח הנדסי / מנהל פרויקט | B20: קומפלט | C20: 1 | D20: 65000 | E20: =C20*D20 | F20: =E20*'סיכום'!$B$5 | G20: =E20+F20 | H20: 0 | I20: =G20-H20 | J20: =IF(G20>0,H20/G20,0)
A21: סה"כ 2. תכנון, ייעוץ והיתרים | E21: =SUM(E14:E20) | F21: =SUM(F14:F20) | G21: =SUM(G14:G20) | H21: =SUM(H14:H20) | I21: =SUM(I14:I20) | J21: =IF(G21>0,H21/G21,0)
A23: 3. עבודות עפר והכשרת קרקע
A24: חפירה, יישור ופינוי עודף | B24: מ"ר | C24: 250 | D24: 55 | E24: =C24*D24 | F24: =E24*'סיכום'!$B$5 | G24: =E24+F24 | H24: 0 | I24: =G24-H24 | J24: =IF(G24>0,H24/G24,0)
A25: מילוי מובא והידוק | B25: מ"ק | C25: 120 | D25: 90 | E25: =C25*D25 | F25: =E25*'סיכום'!$B$5 | G25: =E25+F25 | H25: 0 | I25: =G25-H25 | J25: =IF(G25>0,H25/G25,0)
A26: דיפון / קירות תמך | B26: מ"ר | C26: 0 | D26: 350 | E26: =C26*D26 | F26: =E26*'סיכום'!$B$5 | G26: =E26+F26 | H26: 0 | I26: =G26-H26 | J26: =IF(G26>0,H26/G26,0) | K26: רק אם נדרש טופוגרפית
A27: התארגנות אתר (גידור, חיבור זמני) | B27: קומפלט | C27: 1 | D27: 12000 | E27: =C27*D27 | F27: =E27*'סיכום'!$B$5 | G27: =E27+F27 | H27: 0 | I27: =G27-H27 | J27: =IF(G27>0,H27/G27,0)
A28: סה"כ 3. עבודות עפר והכשרת קרקע | E28: =SUM(E24:E27) | F28: =SUM(F24:F27) | G28: =SUM(G24:G27) | H28: =SUM(H24:H27) | I28: =SUM(I24:I27) | J28: =IF(G28>0,H28/G28,0)
A30: 4. שלד ובטון
A31: יסודות ורפסודת בטון | B31: מ"ר | C31: ='סיכום'!$B$4 | D31: 480 | E31: =C31*D31 | F31: =E31*'סיכום'!$B$5 | G31: =E31+F31 | H31: 0 | I31: =G31-H31 | J31: =IF(G31>0,H31/G31,0)
A32: שלד בטון - עמודים, קורות ותקרות | B32: מ"ר | C32: ='סיכום'!$B$4 | D32: 1150 | E32: =C32*D32 | F32: =E32*'סיכום'!$B$5 | G32: =E32+F32 | H32: 0 | I32: =G32-H32 | J32: =IF(G32>0,H32/G32,0)
A33: ממ"ד (מרחב מוגן) | B33: קומפלט | C33: 1 | D33: 38000 | E33: =C33*D33 | F33: =E33*'סיכום'!$B$5 | G33: =E33+F33 | H33: 0 | I33: =G33-H33 | J33: =IF(G33>0,H33/G33,0)
A34: מדרגות בטון פנים | B34: קומפלט | C34: 1 | D34: 14000 | E34: =C34*D34 | F34: =E34*'סיכום'!$B$5 | G34: =E34+F34 | H34: 0 | I34: =G34-H34 | J34: =IF(G34>0,H34/G34,0)
A35: משאבת בטון ואביזרים | B35: קומפלט | C35: 1 | D35: 9000 | E35: =C35*D35 | F35: =E35*'סיכום'!$B$5 | G35: =E35+F35 | H35: 0 | I35: =G35-H35 | J35: =IF(G35>0,H35/G35,0)
A36: סה"כ 4. שלד ובטון | E36: =SUM(E31:E35) | F36: =SUM(F31:F35) | G36: =SUM(G31:G35) | H36: =SUM(H31:H35) | I36: =SUM(I31:I35) | J36: =IF(G36>0,H36/G36,0)
A38: 5. בנייה, מעטפת ואיטום
A39: בנייה - בלוקים וקירות | B39: מ"ר | C39: ='סיכום'!$B$4 | D39: 380 | E39: =C39*D39 | F39: =E39*'סיכום'!$B$5 | G39: =E39+F39 | H39: 0 | I39: =G39-H39 | J39: =IF(G39>0,H39/G39,0)
A40: איטום (גג, יסודות, חדרים רטובים) | B40: מ"ר | C40: ='סיכום'!$B$4 | D40: 130 | E40: =C40*D40 | F40: =E40*'סיכום'!$B$5 | G40: =E40+F40 | H40: 0 | I40: =G40-H40 | J40: =IF(G40>0,H40/G40,0)
A41: בידוד תרמי ואקוסטי | B41: מ"ר | C41: ='סיכום'!$B$4 | D41: 95 | E41: =C41*D41 | F41: =E41*'סיכום'!$B$5 | G41: =E41+F41 | H41: 0 | I41: =G41-H41 | J41: =IF(G41>0,H41/G41,0)
A42: גג רעפים / גג שטוח | B42: מ"ר | C42: 110 | D42: 320 | E42: =C42*D42 | F42: =E42*'סיכום'!$B$5 | G42: =E42+F42 | H42: 0 | I42: =G42-H42 | J42: =IF(G42>0,H42/G42,0)
A43: סה"כ 5. בנייה, מעטפת ואיטום | E43: =SUM(E39:E42) | F43: =SUM(F39:F42) | G43: =SUM(G39:G42) | H43: =SUM(H39:H42) | I43: =SUM(I39:I42) | J43: =IF(G43>0,H43/G43,0)
A45: 6. אלומיניום ונגרות חוץ
A46: חלונות, ויטרינות ותריסים | B46: מ"ר | C46: 38 | D46: 2300 | E46: =C46*D46 | F46: =E46*'סיכום'!$B$5 | G46: =E46+F46 | H46: 0 | I46: =G46-H46 | J46: =IF(G46>0,H46/G46,0)
...

Sheet מימון ותזרים
A1: מימון ותזרים מזומנים
A3: מקורות מימון
A4: מקור | B4: סכום
A5: הון עצמי / חיסכון | B5: 0
A6: משכנתא | B6: 0
A7: הלוואת גישור / משלימה | B7: 0
A8: מענקים / סיוע / מתנה | B8: 0
A9: מקורות נוספים | B9: 0
A10: סה"כ מקורות מימון | B10: =SUM(B5:B9)
A12: בדיקת איזון תקציב מול מימון
A13: סה"כ תקציב הפרויקט | B13: ='סיכום'!$B$23
A14: סה"כ מקורות מימון | B14: =B10
A15: פער (עודף / גירעון) | B15: =B14-B13
A17: תזרים מזומנים חודשי (תבנית ל-18 חודשים)
A18: חודש | B18: שלב עיקרי | C18: תשלום מתוכנן | D18: תשלום בפועל | E18: מצטבר בפועל
A19: 1 | B19: היתרים, אגרות וחיבורי תשתית | C19: 0 | D19: 0 | E19: =D19
A20: 2 | B20: עבודות עפר ויסודות | C20: 0 | D20: 0 | E20: =E19+D20
A21: 3 | B21: יסודות ותחילת שלד | C21: 0 | D21: 0 | E21: =E20+D21
A22: 4 | B22: שלד בטון | C22: 0 | D22: 0 | E22: =E21+D22
A23: 5 | B23: שלד וגג | C23: 0 | D23: 0 | E23: =E22+D23
A24: 6 | B24: בנייה ומעטפת | C24: 0 | D24: 0 | E24: =E23+D24
A25: 7 | B25: איטום ובידוד | C25: 0 | D25: 0 | E25: =E24+D25
A26: 8 | B26: אינסטלציה וחשמל גס | C26: 0 | D26: 0 | E26: =E25+D26
A27: 9 | B27: טיח פנים וחוץ | C27: 0 | D27: 0 | E27: =E26+D27
A28: 10 | B28: חלונות ואלומיניום | C28: 0 | D28: 0 | E28: =E27+D28
A29: 11 | B29: ריצוף וחיפוי | C29: 0 | D29: 0 | E29: =E28+D29
A30: 12 | B30: מיזוג אוויר | C30: 0 | D30: 0 | E30: =E29+D30
A31: 13 | B31: גבס, תקרות וצבע | C31: 0 | D31: 0 | E31: =E30+D31
... A36: 18 | B36: ניקיון, טופס 4 ומסירה | C36: 0 | D36: 0 | E36: =E35+D36
B37: סה"כ | C37: =SUM(C19:C36) | D37: =SUM(D19:D36) | E37: =E36
